<?xml version="1.0"?>
<robot name="gobot">
  <link name="base_link">
    <visual>
      <geometry>
        <box size="0.629 .500 .097"/>
      </geometry>
      <material name="white">
         <color rgba="1 1 1 .5"/>
    </material>
    </visual>
  </link>

  <joint name="laser" type="fixed">
    <origin xyz="0.2795 0.00 0.0785" rpy="0 0 0" />
    <parent link="base_link" />
    <child link="base_laser" />
  </joint>

  <link name="base_laser">
    <visual>
      <geometry>
        <box size="0.00 0.05 0.06" />
      </geometry>
      <material name="Green" />
    </visual>
    <inertial>
      <mass value="0.000001" />
      <origin xyz="0 0 0" />
      <inertia ixx="0.0001" ixy="0.0" ixz="0.0" iyy="0.0001" iyz="0.0" izz="0.0001" />
    </inertial>
  </link>

  <link name="tyer_front_left">
    <visual>
      <geometry>
       <cylinder length=".0304" radius="0.0625"></cylinder>
      </geometry>
      <material name="black">
          <color rgba="0 0 0 1"/>
      </material>
    </visual>
  </link>

  <link name="tyer_front_right">
    <visual>
      <geometry>
       <cylinder length=".0304" radius="0.0625"></cylinder>
      </geometry>
      <material name="black">
          <color rgba="0 0 0 1"/>
      </material>
    </visual>
  </link>

  <link name="tyer_front_right">
    <visual>
      <geometry>
       <cylinder length=".0304" radius="0.0625"></cylinder>
      </geometry>
      <material name="black">
          <color rgba="0 0 0 1"/>
      </material>
    </visual>
  </link>

  <link name="tyer_back">
    <visual>
      <geometry>
       <cylinder length=".0304" radius="0.0625"></cylinder>
      </geometry>
      <material name="white">
          <color rgba="1 1 1 1"/>
      </material>
    </visual>
  </link>

  <joint name="base_to_front_left" type="continuous">
    <origin rpy="1.57075  0  0" xyz="0.1475  0.1585  -0.014"/>
    <parent link="base_link"/>
    <child link="tyer_front_left"/>
    <axis xyz="0 0 1"/>
  </joint>

  <joint name="base_to_front_right" type="continuous">
    <origin rpy="1.57075  0  0" xyz="0.1475  -0.1585  -0.014"/>
    <parent link="base_link"/>
    <child link="tyer_front_right"/>
    <axis xyz="0 0 1"/>
  </joint>

  <joint name="base_to_back" type="continuous">
    <origin rpy="1.57075  0  0" xyz="-0.2525  0  -0.014"/>
    <parent link="base_link"/>
    <child link="tyer_back"/>
    <axis xyz="0 0 1"/>
  </joint>

  <link name="pillar_front_left">
    <visual>
      <geometry>
        <box size="0.05 .005 1.137"/>
      </geometry>
      <material name="silver">
          <color rgba=".86 .86 .86 1"/>
      </material>
    </visual>
  </link>

  <joint name="base_to_pillar_front_left" type="fixed">
    <origin xyz="-0.2525  0.0  0.5685"/>
    <parent link="base_link"/>
    <child link="pillar_front_left"/>
  </joint>

  <link name="robot_head">
    <visual>
      <geometry>
        <sphere radius="0.10"/>
      </geometry>
      <material name="green">
          <color rgba="0 1 0 1"/>
      </material>
    </visual>
  </link>

  <joint name="pillar_to_head" type="fixed">
    <origin xyz="0.0  0.0  0.5715"/>
    <parent link="pillar_front_left"/>
    <child link="robot_head"/>
  </joint>

  <property name="M_PI" value="3.14159"/>
  <property name="SCALE" value="0.0254"/>
</robot>

